Workbook
Name n_Manning: Parameters!$C$6
Name K_sss: Parameters!$C$7
Name f_sss: Parameters!$C$8
Name K_sc: Parameters!$C$9
Name f_sc: Parameters!$C$10
Name V_max: Parameters!$C$11
Name rho_w: Parameters!$C$12
Name g_acc: Parameters!$C$13
Name tau_sss: Parameters!$C$14
Name tau_sc: Parameters!$C$15
Name PCC: Parameters!$C$17
Name PF_method: Parameters!$C$18
Name PF_a: Parameters!$C$19
Name PF_b: Parameters!$C$20
Name GWI_rate: Parameters!$C$21
Name PortionWet: Parameters!$C$22
Name IIF_coef: Parameters!$C$23
Name IIF_C: Parameters!$C$24
Name I_12: Parameters!$C$25
Name I_area_ref: Parameters!$C$26
Name I_area_exp: Parameters!$C$27
Name F_cont: Parameters!$C$28
Name Dens_ref: Parameters!$C$29
Name Dens_basis: Parameters!$C$30
Name Dens_low: Parameters!$C$32
Name Dens_high: Parameters!$C$33
Name EP_low: Parameters!$C$34
Name EP_med: Parameters!$C$35
Name EP_high: Parameters!$C$36
Name PDWF_L_s: 'Grade Calculator'!$C$9
Name PWWF_L_s: 'Grade Calculator'!$C$10

Sheet README
A1: Sewer minimum / maximum grade calculator - Icon Water (ACT) STD-SPE-G-011
A2: Replaces '230508 - Sewer Calcs - Peak Flows, Max Grade, Min Grade - DC.xlsx' (left untouched).
A4: WHAT IT DOES
A5: ACT only. Given a design PDWF (from EP, or typed in) it returns, for each pipe size DN150-DN900, Icon Water's slime-control grade Sss, self-cleansing grade Ssc, the governing minimum (with the absolute minimum), the maximum grade (V_max at PDWF) and a capacity check at PWWF.
A7: HOW TO USE
A8: 1. 'Peak Flows': enter precincts (dwellings, area). PDWF / GWI / IIF / PWWF follow the WSA 02 Appendix B model; every coefficient is on 'Parameters'.
A9: 2. 'Grade Calculator': pick the precinct (or type an EP, or PDWF and PWWF directly). Read Smin / Smax per DN. Yellow = input, green = result.
A10: 3. 'Design Table': the reverse direction - pick DN and depth ratio y/D and read the PDWF that corresponds to it and the grade. No iteration; good for charts and cross-checking.
A11: 4. 'Parameters': n, K_sss, K_sc, f_sss, f_sc, V_max and the flow coefficients.
A12: 5. 'Validation': reproduces the three cases the original sheet solved in Wolfram Alpha.
A14: METHOD (why no Wolfram Alpha is needed)
A15: Icon Water Eq IW.5.5.3.2 is a tractive-force criterion: Sss (%) = 0.0338 / Rp <=> S = K / Rp with K = 0.000338 m, i.e. boundary shear stress tau = rho g Rp S = 3.32 Pa.
... A33: Still site-specific: replace 21.4 mm/h with the Bureau of Meteorology 1-hour 39.35% AEP intensity for the catchment. The supplement illustrates the lookup for central Canberra; it does not print 21.4 as the design value.

Sheet Parameters
A1: Parameters (yellow = editable input)
A2: All calculation sheets reference these cells by defined name (Formulas > Name Manager).
A4: Parameter | B4: Symbol / name | C4: Value | D4: Units | E4: Source / note
A5: Hydraulics - Icon Water STD-SPE-G-011 (supplement to WSA 02-2014)
A6: Manning roughness coefficient (Icon) | B6: n | C6: 0.012 | D6: - | E6: STD-SPE-G-011 Table IW.3 gives 0.011 / 0.012 by material; 0.012 is the conservative value used in the original sheet.
A7: Sulphide slime control coefficient | B7: K_sss | C7: 0.0338 | D7: % x m | E7: Eq IW.5.5.3.2: Sss (%) = 0.0338 / Rp, Rp = hydraulic radius at f_sss x PDWF. Equivalent boundary shear stress tau = K/100 x rho x g = 3.32 Pa.
A8: Flow fraction for slime control | B8: f_sss | C8: 0.75 | D8: - | E8: Eq IW.5.5.3.3: Rp evaluated at 0.75 x PDWF (TPF = 0).
A9: Self-cleansing coefficient | B9: K_sc | C9: 0.0135 | D9: % x m | E9: Eq IW.5.5.3.1: Ssc (%) = 0.0135 / Rp. Same Rp as slime control (Eq IW.5.5.3.3).
A10: Flow fraction in Qdmp | B10: f_sc | C10: 0.75 | D10: - | E10: Eq IW.5.5.3.3: Qdmp = 0.75 x (PDWF + 2/3 TPF). Both Ssc and Sss use Rp at this flow. f_sss is the same factor.
A11: Maximum velocity | B11: V_max | C11: 3 | D11: m/s | E11: IW.5.5.4: maximum grade is the grade at which velocity at PDWF reaches 3.0 m/s. The original sheet used 2.9 m/s with PWWF and carried a note to change to 3.0 m/s and PDWF.
A12: Water density | B12: rho | C12: 1000 | D12: kg/m3 | E12: Shear-stress equivalents only.
A13: Gravity | B13: g | C13: 9.81 | D13: m/s2 | E13: Shear-stress equivalents only.
A14: Shear stress equivalent of K_sss | B14: tau_sss | C14: =K_sss/100*rho_w*g_acc | D14: Pa | E14: Derived - information only.
A15: Shear stress equivalent of K_sc | B15: tau_sc | C15: =K_sc/100*rho_w*g_acc | D15: Pa | E15: Derived - information only.
A16: Flow estimation - STD-SPE-G-011 Version 5 (8 Oct 2025), Section IW.3
A17: ADWF loading | B17: PCC | C17: 180 | D17: L/EP/day | E17: WSA 02 App B2: ADWF = 0.0021 L/s/EP = 180 L/d/EP.
A18: Peaking factor method (1 = a x EP^-b as original; 2 = WSA 02 App B d(area) polynomial) | B18: PF_method | C18: 1 | D18: - | E18: Icon requires method 1: Eqn 3.4.2.3, PDWF = 5.83 x ADWF / TEP^0.1. Method 2 is the old WSA area polynomial and is not used by Icon.
A19: Peaking factor coefficient (method 1) | B19: PF_a | C19: 5.83 | D19: -
A20: Peaking factor exponent (method 1) | B20: PF_b | C20: 0.1 | D20: -
A21: Groundwater infiltration rate | B21: GWI_rate | C21: 0.01875 | D21: L/s/ha | E21: Eqn 3.4.3.1: GWI = 0.01875 x NSA x Portionwet.
A22: Portion of network below groundwater | B22: PortionWet | C22: 0.75 | D22: - | E22: Icon default Portionwet = 0.75, applied once on top of the 0.01875 coefficient.
A23: IIF (RDI) coefficient | B23: IIF_coef | C23: 0.028 | D23: - | E23: WSA 02 App B4: IIF = 0.028 x AEff x C x I.
A24: IIF leakage severity coefficient C | B24: IIF_C | C24: 1.2 | D24: - | E24: WSA 02 Table B1: 0.4 (low) to 1.6 (high). Original sheet 1.2.
A25: 1-hour rainfall intensity at 39.35% AEP | B25: I_12 | C25: 21.4 | D25: mm/h | E25: Eqn 3.4.4.2: I = I(1 hour, 39.35% AEP) x (40/NSA)^0.12 x 1.5. Look the intensity up on the Bureau of Meteorology Design Rainfall Data System for the site. 21.4 is the original spreadsheet figure, not a constant printed in STD-SPE-G-011.
A26: FactorSize reference area | B26: I_area_ref | C26: 40 | D26: ha | E26: FactorSize = (40/A)^0.12 (WSA 02 App B4).
A27: FactorSize exponent | B27: I_area_exp | C27: 0.12 | D27: -
A28: FactorContainment | B28: F_cont | C28: 1.5 | D28: - | E28: WSA 02 Table B3: 1.5 for 10-year ARI containment (SW minimum). Original sheet 1.5.
A29: AEff density reference | B29: Dens_ref | C29: 150 | D29: EP/ha | E29: AEff = A x (Density/150)^0.5 for Density < 150 EP/ha, else AEff = A (WSA 02 App B4).
A30: Density basis for AEff (1 = EP/ha per WSA 02; 0 = dwellings/ha as original sheet) | B30: Dens_basis | C30: 1 | D30: - | E30: WSA 02 defines Density as EP per gross hectare. The original sheet used dwellings/ha, and dropped the factor only where dwellings/ha > 150.
A31: EP per dwelling by dwelling density (original sheet lookup)
A32: Low density threshold (< this = low) | B32: Dens_low | C32: 25 | D32: dw/ha
A33: High density threshold (> this = high) | B33: Dens_high | C33: 80 | D33: dw/ha
A34: EP/dwelling - low density | B34: EP_low | C34: 3.5 | D34: EP | E34: Table IW.1: low density, under 25 dwellings per hectare NSA.
A35: EP/dwelling - medium density | B35: EP_med | C35: 2.5 | D35: EP
A36: EP/dwelling - high density | B36: EP_high | C36: 2 | D36: EP

Sheet Peak Flows
A1: Design flow estimation by precinct - WSA 02 Appendix B model (PDWF + GWI + IIF)
A2: Inputs: precinct id, dwellings, area (ha). EP/dwelling is looked up from dwelling density. Coefficients live on 'Parameters'. PWWF here = WSA 02 'design flow' = PDWF + GWI + IIF (the original sheet called IIF 'RDI').
A4: Precinct | B4: Dwellings | C4: Area (ha) | D4: Dwelling density (dw/ha) | E4: EP / dwelling | F4: Total EP | G4: EP density (EP/ha) | H4: ADWF (L/s) | I4: Peaking factor d | J4: PDWF (L/s) | K4: GWI (L/s) | L4: AEff factor | M4: I (mm/h) | N4: IIF / RDI (L/s) | O4: PWWF = design flow (L/s)
A5: 1 | B5: 78 | C5: 1.54 | D5: =IF(C5=0,0,B5/C5) | E5: =IF(B5=0,0,IF(D5<Dens_low,EP_low,IF(D5<=Dens_high,EP_med,EP_high))) | F5: =E5*B5 | G5: =IF(C5=0,0,F5/C5) | H5: =F5*PCC/86400 | I5: =IF(F5<=0,0,IF(PF_method=2,IF(C5<=0,0,0.01*LOG10(C5)^4-0.19*LOG10(C5)^3+1.4*LOG10(C5)^2-4.66*LOG10(C5)+7.57),PF_a/F5^PF_b)) | J5: =I5*H5 | K5: =GWI_rate*C5*PortionWet | L5: =IF(C5=0,0,IF(Dens_basis=1,MIN(1,SQRT(G5/Dens_ref)),MIN(1,SQRT(D5/Dens_ref)))) | M5: =IF(C5=0,0,I_12*(I_area_ref/C5)^I_area_exp*F_cont) | N5: =C5*L5*IIF_coef*IIF_C*M5 | O5: =J5+K5+N5
A6: 2 | B6: 207 | C6: 2.25 | D6: =IF(C6=0,0,B6/C6) | E6: =IF(B6=0,0,IF(D6<Dens_low,EP_low,IF(D6<=Dens_high,EP_med,EP_high))) | F6: =E6*B6 | G6: =IF(C6=0,0,F6/C6) | H6: =F6*PCC/86400 | I6: =IF(F6<=0,0,IF(PF_method=2,IF(C6<=0,0,0.01*LOG10(C6)^4-0.19*LOG10(C6)^3+1.4*LOG10(C6)^2-4.66*LOG10(C6)+7.57),PF_a/F6^PF_b)) | J6: =I6*H6 | K6: =GWI_rate*C6*PortionWet | L6: =IF(C6=0,0,IF(Dens_basis=1,MIN(1,SQRT(G6/Dens_ref)),MIN(1,SQRT(D6/Dens_ref)))) | M6: =IF(C6=0,0,I_12*(I_area_ref/C6)^I_area_exp*F_cont) | N6: =C6*L6*IIF_coef*IIF_C*M6 | O6: =J6+K6+N6
A7: 3 | B7: 156 | C7: 0.8 | D7: =IF(C7=0,0,B7/C7) | E7: =IF(B7=0,0,IF(D7<Dens_low,EP_low,IF(D7<=Dens_high,EP_med,EP_high))) | F7: =E7*B7 | G7: =IF(C7=0,0,F7/C7) | H7: =F7*PCC/86400 | I7: =IF(F7<=0,0,IF(PF_method=2,IF(C7<=0,0,0.01*LOG10(C7)^4-0.19*LOG10(C7)^3+1.4*LOG10(C7)^2-4.66*LOG10(C7)+7.57),PF_a/F7^PF_b)) | J7: =I7*H7 | K7: =GWI_rate*C7*PortionWet | L7: =IF(C7=0,0,IF(Dens_basis=1,MIN(1,SQRT(G7/Dens_ref)),MIN(1,SQRT(D7/Dens_ref)))) | M7: =IF(C7=0,0,I_12*(I_area_ref/C7)^I_area_exp*F_cont) | N7: =C7*L7*IIF_coef*IIF_C*M7 | O7: =J7+K7+N7
A8: 4 | B8: 124 | C8: 0.44 | D8: =IF(C8=0,0,B8/C8) | E8: =IF(B8=0,0,IF(D8<Dens_low,EP_low,IF(D8<=Dens_high,EP_med,EP_high))) | F8: =E8*B8 | G8: =IF(C8=0,0,F8/C8) | H8: =F8*PCC/86400 | I8: =IF(F8<=0,0,IF(PF_method=2,IF(C8<=0,0,0.01*LOG10(C8)^4-0.19*LOG10(C8)^3+1.4*LOG10(C8)^2-4.66*LOG10(C8)+7.57),PF_a/F8^PF_b)) | J8: =I8*H8 | K8: =GWI_rate*C8*PortionWet | L8: =IF(C8=0,0,IF(Dens_basis=1,MIN(1,SQRT(G8/Dens_ref)),MIN(1,SQRT(D8/Dens_ref)))) | M8: =IF(C8=0,0,I_12*(I_area_ref/C8)^I_area_exp*F_cont) | N8: =C8*L8*IIF_coef*IIF_C*M8 | O8: =J8+K8+N8
A9: 5 | B9: 159 | C9: 0.84 | D9: =IF(C9=0,0,B9/C9) | E9: =IF(B9=0,0,IF(D9<Dens_low,EP_low,IF(D9<=Dens_high,EP_med,EP_high))) | F9: =E9*B9 | G9: =IF(C9=0,0,F9/C9) | H9: =F9*PCC/86400 | I9: =IF(F9<=0,0,IF(PF_method=2,IF(C9<=0,0,0.01*LOG10(C9)^4-0.19*LOG10(C9)^3+1.4*LOG10(C9)^2-4.66*LOG10(C9)+7.57),PF_a/F9^PF_b)) | J9: =I9*H9 | K9: =GWI_rate*C9*PortionWet | L9: =IF(C9=0,0,IF(Dens_basis=1,MIN(1,SQRT(G9/Dens_ref)),MIN(1,SQRT(D9/Dens_ref)))) | M9: =IF(C9=0,0,I_12*(I_area_ref/C9)^I_area_exp*F_cont) | N9: =C9*L9*IIF_coef*IIF_C*M9 | O9: =J9+K9+N9
A10: 6 | B10: 175 | C10: 1.38 | D10: =IF(C10=0,0,B10/C10) | E10: =IF(B10=0,0,IF(D10<Dens_low,EP_low,IF(D10<=Dens_high,EP_med,EP_high))) | F10: =E10*B10 | G10: =IF(C10=0,0,F10/C10) | H10: =F10*PCC/86400 | I10: =IF(F10<=0,0,IF(PF_method=2,IF(C10<=0,0,0.01*LOG10(C10)^4-0.19*LOG10(C10)^3+1.4*LOG10(C10)^2-4.66*LOG10(C10)+7.57),PF_a/F10^PF_b)) | J10: =I10*H10 | K10: =GWI_rate*C10*PortionWet | L10: =IF(C10=0,0,IF(Dens_basis=1,MIN(1,SQRT(G10/Dens_ref)),MIN(1,SQRT(D10/Dens_ref)))) | M10: =IF(C10=0,0,I_12*(I_area_ref/C10)^I_area_exp*F_cont) | N10: =C10*L10*IIF_coef*IIF_C*M10 | O10: =J10+K10+N10
A11: 7 | B11: 121 | C11: 1.04 | D11: =IF(C11=0,0,B11/C11) | E11: =IF(B11=0,0,IF(D11<Dens_low,EP_low,IF(D11<=Dens_high,EP_med,EP_high))) | F11: =E11*B11 | G11: =IF(C11=0,0,F11/C11) | H11: =F11*PCC/86400 | I11: =IF(F11<=0,0,IF(PF_method=2,IF(C11<=0,0,0.01*LOG10(C11)^4-0.19*LOG10(C11)^3+1.4*LOG10(C11)^2-4.66*LOG10(C11)+7.57),PF_a/F11^PF_b)) | J11: =I11*H11 | K11: =GWI_rate*C11*PortionWet | L11: =IF(C11=0,0,IF(Dens_basis=1,MIN(1,SQRT(G11/Dens_ref)),MIN(1,SQRT(D11/Dens_ref)))) | M11: =IF(C11=0,0,I_12*(I_area_ref/C11)^I_area_exp*F_cont) | N11: =C11*L11*IIF_coef*IIF_C*M11 | O11: =J11+K11+N11
A12: 8 | B12: 42 | C12: 0.358 | D12: =IF(C12=0,0,B12/C12) | E12: =IF(B12=0,0,IF(D12<Dens_low,EP_low,IF(D12<=Dens_high,EP_med,EP_high))) | F12: =E12*B12 | G12: =IF(C12=0,0,F12/C12) | H12: =F12*PCC/86400 | I12: =IF(F12<=0,0,IF(PF_method=2,IF(C12<=0,0,0.01*LOG10(C12)^4-0.19*LOG10(C12)^3+1.4*LOG10(C12)^2-4.66*LOG10(C12)+7.57),PF_a/F12^PF_b)) | J12: =I12*H12 | K12: =GWI_rate*C12*PortionWet | L12: =IF(C12=0,0,IF(Dens_basis=1,MIN(1,SQRT(G12/Dens_ref)),MIN(1,SQRT(D12/Dens_ref)))) | M12: =IF(C12=0,0,I_12*(I_area_ref/C12)^I_area_exp*F_cont) | N12: =C12*L12*IIF_coef*IIF_C*M12 | O12: =J12+K12+N12
A13: 9 | B13: 30 | C13: 0.71 | D13: =IF(C13=0,0,B13/C13) | E13: =IF(B13=0,0,IF(D13<Dens_low,EP_low,IF(D13<=Dens_high,EP_med,EP_high))) | F13: =E13*B13 | G13: =IF(C13=0,0,F13/C13) | H13: =F13*PCC/86400 | I13: =IF(F13<=0,0,IF(PF_method=2,IF(C13<=0,0,0.01*LOG10(C13)^4-0.19*LOG10(C13)^3+1.4*LOG10(C13)^2-4.66*LOG10(C13)+7.57),PF_a/F13^PF_b)) | J13: =I13*H13 | K13: =GWI_rate*C13*PortionWet | L13: =IF(C13=0,0,IF(Dens_basis=1,MIN(1,SQRT(G13/Dens_ref)),MIN(1,SQRT(D13/Dens_ref)))) | M13: =IF(C13=0,0,I_12*(I_area_ref/C13)^I_area_exp*F_cont) | N13: =C13*L13*IIF_coef*IIF_C*M13 | O13: =J13+K13+N13
A14: 10 | B14: 0 | C14: 3.19 | D14: =IF(C14=0,0,B14/C14) | E14: =IF(B14=0,0,IF(D14<Dens_low,EP_low,IF(D14<=Dens_high,EP_med,EP_high))) | F14: =E14*B14 | G14: =IF(C14=0,0,F14/C14) | H14: =F14*PCC/86400 | I14: =IF(F14<=0,0,IF(PF_method=2,IF(C14<=0,0,0.01*LOG10(C14)^4-0.19*LOG10(C14)^3+1.4*LOG10(C14)^2-4.66*LOG10(C14)+7.57),PF_a/F14^PF_b)) | J14: =I14*H14 | K14: =GWI_rate*C14*PortionWet | L14: =IF(C14=0,0,IF(Dens_basis=1,MIN(1,SQRT(G14/Dens_ref)),MIN(1,SQRT(D14/Dens_ref)))) | M14: =IF(C14=0,0,I_12*(I_area_ref/C14)^I_area_exp*F_cont) | N14: =C14*L14*IIF_coef*IIF_C*M14 | O14: =J14+K14+N14
A16: Sum of precincts | B16: =SUM(B5:B14) | C16: =SUM(C5:C14) | F16: =SUM(F5:F14) | H16: =SUM(H5:H14) | J16: =SUM(J5:J14) | K16: =SUM(K5:K14) | N16: =SUM(N5:N14) | O16: =SUM(O5:O14)
A17: Combined system (peaking factor on total EP / total area) | C17: =C16 | F17: =F16 | H17: =H16 | I17: =IF(F17<=0,0,IF(PF_method=2,IF(C17<=0,0,0.01*LOG10(C17)^4-0.19*LOG10(C17)^3+1.4*LOG10(C17)^2-4.66*LOG10(C17)+7.57),PF_a/F17^PF_b)) | J17: =I17*H17 | K17: =K16 | N17: =N16 | O17: =J17+K17+N17
A19: Notes: (1) the peaking factor falls with EP (or area), so summing precinct PDWFs over-estimates the PDWF of the combined catchment - use the 'Combined system' row for a trunk serving all precincts (the original summed PWWF = 28.2 L/s). (2) Precinct 10 (0 dwellings) previously gave #DIV/0!. (3) With the original settings (PF_method 1, Dens_basis 0, PortionWet applied once) precinct 2 gives PDWF 2.75 L/s and PWWF 5.48 L/s (original 5.47 - the 0.01 difference is the GWI double-factor).

Sheet Grade Calculator
A1: Minimum and maximum sewer grade by pipe size - Icon Water (ACT) STD-SPE-G-011, supplement to WSA 02-2014 - explicit solution, no Wolfram Alpha
A2: ACT only. Grades are in % (1.000 = 1 % = 1 in 100). Use 'Solve for' to pick the unknown: Grade (from flow and DN), Flow (from a grade and DN), or Diameter (smallest DN whose minimum grade is no steeper than the grade you can build). The table below is always the grade-from-flow direction for every DN.
A4: Precinct (from 'Peak Flows') | C4: 2 | E4: Legend: | F4: input | G4: calculated | I4: Solve for | J4: Grade
A5: Manual EP override (0 = use precinct) | C5: 0 | I5: DN | J5: 225
A6: Manual PDWF override (L/s, 0 = off) | C6: 0 | I6: Grade (%) — input for Flow and Diameter | J6: 1
A7: Manual PWWF override (L/s, 0 = off) | C7: 0
A8: EP used | C8: =IF(C6>0,"n/a",IF(C5>0,C5,IFERROR(INDEX('Peak Flows'!$F$5:$F$14,MATCH(C4,'Peak Flows'!$A$5:$A$14,0)),0))) | I8: Answer | J8: =IF($J$4="Grade",INDEX($R$16:$R$25,MATCH($J$5,$A$16:$A$25,0)),IF($J$4="Flow",IF(OR($J$6<=0,$J$5=""),"",IF(Calc!C28<=0,"grade flatter than a full pipe",(1/n_Manning)*(($J$5/1000)^2*(Calc!R28-SIN(Calc!R28))/8)*(Calc!C28^(2/3))*SQRT($J$6/100)*1000)),IF($J$4="Diameter",IFERROR(AGGREGATE(15,6,$A$16:$A$25/(($R$16:$R$25<=$J$6)*(IF(ISNUMBER($Y$16:$Y$25),$Y$16:$Y$25>=$R$16:$R$25,1))*(($AA$16:$AA$25>=PWWF_L_s)+(PWWF_L_s<=0))),1),"none"),"")))
A9: PDWF used (L/s) | C9: =IF(C6>0,C6,IF(C5>0,IF(PF_method=2,"set PF_method=1 or enter PDWF",PF_a*(C5*PCC/86400)/C5^PF_b),IFERROR(INDEX('Peak Flows'!$J$5:$J$14,MATCH(C4,'Peak Flows'!$A$5:$A$14,0)),0))) | I9: What the answer is | J9: =IF($J$4="Grade","Governing minimum grade (%) for the DN",IF($J$4="Flow","Qdmp (L/s) at which this grade equals Sss. PDWF = Qdmp/f_sss - (2/3) TPF when that is positive.",IF($J$4="Diameter","Smallest DN whose minimum grade is no steeper than the grade entered, which can still carry PWWF, and whose maximum grade is steeper than its minimum.","")))
A10: PWWF used (L/s) - capacity check only | C10: =IF(C7>0,C7,IF(OR(C6>0,C5>0),0,IFERROR(INDEX('Peak Flows'!$O$5:$O$14,MATCH(C4,'Peak Flows'!$A$5:$A$14,0)),0))) | I10: Also | J10: =IF($J$4="Grade",INDEX($T$16:$T$25,MATCH($J$5,$A$16:$A$25,0)),IF($J$4="Flow",IF(ISNUMBER(J8),J8/f_sss-(2/3)*$C$13,""),IF($J$4="Diameter",IF(ISNUMBER(J8),INDEX($R$16:$R$25,MATCH(J8,$A$16:$A$25,0)),""),"")))
A11: Qdmp = f_sss x (PDWF + 2/3 TPF) (L/s) | C11: =f_sss*(C9+(2/3)*C13) | I11: Also means | J11: =IF($J$4="Grade","Which criterion governs",IF($J$4="Flow","PDWF (L/s) for that slime-control grade, after pumped flow",IF($J$4="Diameter","That DN's governing minimum grade (%)","")))
A12: Q for self-cleansing = same Qdmp (L/s) | C12: =C11 | I12: Self-cleansing flow at the same grade (L/s Qdmp) | J12: =IF($J$4="Flow",IF(OR($J$6<=0,$J$5=""),"",IF(Calc!C29<=0,"grade flatter than a full pipe",(1/n_Manning)*(($J$5/1000)^2*(Calc!R29-SIN(Calc!R29))/8)*(Calc!C29^(2/3))*SQRT($J$6/100)*1000)),"")
A13: Total pumped flow TPF (L/s, 0 if none) | C13: 0
A14: DN150 only: ultimate houses draining to the line | C14: Sulphide slime control Sss = K_sss / Rp at f_sss x PDWF (Eq IW.5.5.3.2 / 3.3) | K14: Self-cleansing Ssc = K_sc / Rp at f_sc x PDWF (Eq IW.5.5.3.1 - verify K_sc) | Q14: Governing minimum grade | U14: Maximum grade (V = V_max at PDWF, IW.5.5.4) | AA14: Capacity check at the governing minimum grade (PWWF)
A15: DN | B15: D (m) | C15: Q75 (L/s) | D15: theta (rad) | E15: y (mm) | F15: y/D | G15: Rp (m) | H15: V (m/s) | I15: Sss (%) | J15: Sss (1 in) | K15: Qsc (L/s) | L15: theta (rad) | M15: y/D | N15: Rp (m) | O15: V (m/s) | P15: Ssc (%) | Q15: Absolute min (%) 80/ID or Table IW.4 | R15: Governing Smin (%) | S15: Smin (1 in) | T15: Governing criterion | U15: A = PDWF/V_max (m2) | V15: theta (rad) | W15: y/D | X15: R (m) | Y15: Smax (%) | Z15: Smax (1 in) | AA15: Q full at Smin (L/s) | AB15: PWWF / Qfull | AC15: y/D at PWWF | AD15: V at PWWF (m/s) | AE15: PDWF / Qfull | AF15: Status
A16: 150 | B16: =A16/1000 | C16: =$C$11 | D16: =Calc!R16 | E16: =IF(D16=0,"",$B16/2*(1-COS(D16/2))*1000) | F16: =IF(D16=0,"",(1-COS(D16/2))/2) | G16: =IF(D16=0,"",($B16/4)*(1-SIN(D16)/D16)) | H16: =IF(D16=0,"",(C16/1000)/($B16^2*(D16-SIN(D16))/8)) | I16: =IF(D16=0,"",K_sss/G16) | J16: =IF(D16=0,"",100/I16) | K16: =$C$12 | L16: =Calc!AI16 | M16: =IF(L16=0,"",(1-COS(L16/2))/2) | N16: =IF(L16=0,"",($B16/4)*(1-SIN(L16)/L16)) | O16: =IF(L16=0,"",(K16/1000)/($B16^2*(L16-SIN(L16))/8)) | P16: =IF(L16=0,"",K_sc/N16) | Q16: =IF(A16<=150,IF($C$14>=35,0.7,IF($C$14>=28,0.8,IF($C$14>=18,0.9,IF($C$14>=12,1,IF($C$14>=7,1.1,IF($C$14>=2,1.2,IF($C$14>=1,1.25,""))))))),80/A16) | R16: =IF(A16<=150,IF(ISNUMBER(Q16),Q16,""),MAX(IF(ISNUMBER(I16),I16,0),IF(ISNUMBER(P16),P16,0),IF(ISNUMBER(Q16),Q16,0))) | S16: =IF(OR(R16="",R16<=0),"",100/R16) | T16: =IF(A16<=150,"DN150 Table IW.4",IF(OR(R16="",R16<=0),"no flow",IF(R16=Q16,"Absolute minimum (80/ID)",IF(AND(ISNUMBER(I16),R16=I16),"Slime control (Sss)","Self-cleansing (Ssc)")))) | U16: =IF(PDWF_L_s<=0,"",(PDWF_L_s/1000)/V_max) | V16: =Calc!AZ16 | W16: =IF(V16=0,"",(1-COS(V16/2))/2) | X16: =IF(V16=0,"",($B16/4)*(1-SIN(V16)/V16)) | Y16: =IF(V16=0,"",IF(U16>=PI()*$B16^2/4,"n/a - full",((V_max*n_Manning)/(X16^(2/3)))^2*100)) | Z16: =IF(ISNUMBER(Y16),100/Y16,"") | AA16: =IF(R16<=0,"",(1/n_Manning)*(PI()*$B16^2/4)*($B16/4)^(2/3)*SQRT(R16/100)*1000) | AB16: =IF(OR(PWWF_L_s<=0,R16<=0),"",PWWF_L_s/AA16) | AC16: =IF(OR(PWWF_L_s<=0,R16<=0),"",IF(AB16>=1,">1 (full)",(1-COS(Calc!BQ16/2))/2)) | AD16: =IF(OR(PWWF_L_s<=0,R16<=0),"",IF(AB16>=1,PWWF_L_s/1000/(PI()*$B16^2/4),(PWWF_L_s/1000)/($B16^2*(Calc!BQ16-SIN(Calc!BQ16))/8))) | AE16: =IF(OR(PDWF_L_s<=0,R16<=0),"",PDWF_L_s/AA16) | AF16: =IF(PDWF_L_s<=0,"enter flow",IF(OR(F16>0.95,M16>0.95),"Pipe too small for PDWF",IF(AND(ISNUMBER(Y16),Y16<R16),"Smax < Smin - pipe too large for flow",IF(PWWF_L_s<=0,"PWWF not set",IF(AB16>1,"SURCHARGED at Smin - size up or steepen","OK")))))
A17: 225 | B17: =A17/1000 | C17: =$C$11 | D17: =Calc!R17 | E17: =IF(D17=0,"",$B17/2*(1-COS(D17/2))*1000) | F17: =IF(D17=0,"",(1-COS(D17/2))/2) | G17: =IF(D17=0,"",($B17/4)*(1-SIN(D17)/D17)) | H17: =IF(D17=0,"",(C17/1000)/($B17^2*(D17-SIN(D17))/8)) | I17: =IF(D17=0,"",K_sss/G17) | J17: =IF(D17=0,"",100/I17) | K17: =$C$12 | L17: =Calc!AI17 | M17: =IF(L17=0,"",(1-COS(L17/2))/2) | N17: =IF(L17=0,"",($B17/4)*(1-SIN(L17)/L17)) | O17: =IF(L17=0,"",(K17/1000)/($B17^2*(L17-SIN(L17))/8)) | P17: =IF(L17=0,"",K_sc/N17) | Q17: =IF(A17<=150,IF($C$14>=35,0.7,IF($C$14>=28,0.8,IF($C$14>=18,0.9,IF($C$14>=12,1,IF($C$14>=7,1.1,IF($C$14>=2,1.2,IF($C$14>=1,1.25,""))))))),80/A17) | R17: =IF(A17<=150,IF(ISNUMBER(Q17),Q17,""),MAX(IF(ISNUMBER(I17),I17,0),IF(ISNUMBER(P17),P17,0),IF(ISNUMBER(Q17),Q17,0))) | S17: =IF(OR(R17="",R17<=0),"",100/R17) | T17: =IF(A17<=150,"DN150 Table IW.4",IF(OR(R17="",R17<=0),"no flow",IF(R17=Q17,"Absolute minimum (80/ID)",IF(AND(ISNUMBER(I17),R17=I17),"Slime control (Sss)","Self-cleansing (Ssc)")))) | U17: =IF(PDWF_L_s<=0,"",(PDWF_L_s/1000)/V_max) | V17: =Calc!AZ17 | W17: =IF(V17=0,"",(1-COS(V17/2))/2) | X17: =IF(V17=0,"",($B17/4)*(1-SIN(V17)/V17)) | Y17: =IF(V17=0,"",IF(U17>=PI()*$B17^2/4,"n/a - full",((V_max*n_Manning)/(X17^(2/3)))^2*100)) | Z17: =IF(ISNUMBER(Y17),100/Y17,"") | AA17: =IF(R17<=0,"",(1/n_Manning)*(PI()*$B17^2/4)*($B17/4)^(2/3)*SQRT(R17/100)*1000) | AB17: =IF(OR(PWWF_L_s<=0,R17<=0),"",PWWF_L_s/AA17) | AC17: =IF(OR(PWWF_L_s<=0,R17<=0),"",IF(AB17>=1,">1 (full)",(1-COS(Calc!BQ17/2))/2)) | AD17: =IF(OR(PWWF_L_s<=0,R17<=0),"",IF(AB17>=1,PWWF_L_s/1000/(PI()*$B17^2/4),(PWWF_L_s/1000)/($B17^2*(Calc!BQ17-SIN(Calc!BQ17))/8))) | AE17: =IF(OR(PDWF_L_s<=0,R17<=0),"",PDWF_L_s/AA17) | AF17: =IF(PDWF_L_s<=0,"enter flow",IF(OR(F17>0.95,M17>0.95),"Pipe too small for PDWF",IF(AND(ISNUMBER(Y17),Y17<R17),"Smax < Smin - pipe too large for flow",IF(PWWF_L_s<=0,"PWWF not set",IF(AB17>1,"SURCHARGED at Smin - size up or steepen","OK")))))
A18: 300 | B18: =A18/1000 | C18: =$C$11 | D18: =Calc!R18 | E18: =IF(D18=0,"",$B18/2*(1-COS(D18/2))*1000) | F18: =IF(D18=0,"",(1-COS(D18/2))/2) | G18: =IF(D18=0,"",($B18/4)*(1-SIN(D18)/D18)) | H18: =IF(D18=0,"",(C18/1000)/($B18^2*(D18-SIN(D18))/8)) | I18: =IF(D18=0,"",K_sss/G18) | J18: =IF(D18=0,"",100/I18) | K18: =$C$12 | L18: =Calc!AI18 | M18: =IF(L18=0,"",(1-COS(L18/2))/2) | N18: =IF(L18=0,"",($B18/4)*(1-SIN(L18)/L18)) | O18: =IF(L18=0,"",(K18/1000)/($B18^2*(L18-SIN(L18))/8)) | P18: =IF(L18=0,"",K_sc/N18) | Q18: =IF(A18<=150,IF($C$14>=35,0.7,IF($C$14>=28,0.8,IF($C$14>=18,0.9,IF($C$14>=12,1,IF($C$14>=7,1.1,IF($C$14>=2,1.2,IF($C$14>=1,1.25,""))))))),80/A18) | R18: =IF(A18<=150,IF(ISNUMBER(Q18),Q18,""),MAX(IF(ISNUMBER(I18),I18,0),IF(ISNUMBER(P18),P18,0),IF(ISNUMBER(Q18),Q18,0))) | S18: =IF(OR(R18="",R18<=0),"",100/R18) | T18: =IF(A18<=150,"DN150 Table IW.4",IF(OR(R18="",R18<=0),"no flow",IF(R18=Q18,"Absolute minimum (80/ID)",IF(AND(ISNUMBER(I18),R18=I18),"Slime control (Sss)","Self-cleansing (Ssc)")))) | U18: =IF(PDWF_L_s<=0,"",(PDWF_L_s/1000)/V_max) | V18: =Calc!AZ18 | W18: =IF(V18=0,"",(1-COS(V18/2))/2) | X18: =IF(V18=0,"",($B18/4)*(1-SIN(V18)/V18)) | Y18: =IF(V18=0,"",IF(U18>=PI()*$B18^2/4,"n/a - full",((V_max*n_Manning)/(X18^(2/3)))^2*100)) | Z18: =IF(ISNUMBER(Y18),100/Y18,"") | AA18: =IF(R18<=0,"",(1/n_Manning)*(PI()*$B18^2/4)*($B18/4)^(2/3)*SQRT(R18/100)*1000) | AB18: =IF(OR(PWWF_L_s<=0,R18<=0),"",PWWF_L_s/AA18) | AC18: =IF(OR(PWWF_L_s<=0,R18<=0),"",IF(AB18>=1,">1 (full)",(1-COS(Calc!BQ18/2))/2)) | AD18: =IF(OR(PWWF_L_s<=0,R18<=0),"",IF(AB18>=1,PWWF_L_s/1000/(PI()*$B18^2/4),(PWWF_L_s/1000)/($B18^2*(Calc!BQ18-SIN(Calc!BQ18))/8))) | AE18: =IF(OR(PDWF_L_s<=0,R18<=0),"",PDWF_L_s/AA18) | AF18: =IF(PDWF_L_s<=0,"enter flow",IF(OR(F18>0.95,M18>0.95),"Pipe too small for PDWF",IF(AND(ISNUMBER(Y18),Y18<R18),"Smax < Smin - pipe too large for flow",IF(PWWF_L_s<=0,"PWWF not set",IF(AB18>1,"SURCHARGED at Smin - size up or steepen","OK")))))
A19: 375 | B19: =A19/1000 | C19: =$C$11 | D19: =Calc!R19 | E19: =IF(D19=0,"",$B19/2*(1-COS(D19/2))*1000) | F19: =IF(D19=0,"",(1-COS(D19/2))/2) | G19: =IF(D19=0,"",($B19/4)*(1-SIN(D19)/D19)) | H19: =IF(D19=0,"",(C19/1000)/($B19^2*(D19-SIN(D19))/8)) | I19: =IF(D19=0,"",K_sss/G19) | J19: =IF(D19=0,"",100/I19) | K19: =$C$12 | L19: =Calc!AI19 | M19: =IF(L19=0,"",(1-COS(L19/2))/2) | N19: =IF(L19=0,"",($B19/4)*(1-SIN(L19)/L19)) | O19: =IF(L19=0,"",(K19/1000)/($B19^2*(L19-SIN(L19))/8)) | P19: =IF(L19=0,"",K_sc/N19) | Q19: =IF(A19<=150,IF($C$14>=35,0.7,IF($C$14>=28,0.8,IF($C$14>=18,0.9,IF($C$14>=12,1,IF($C$14>=7,1.1,IF($C$14>=2,1.2,IF($C$14>=1,1.25,""))))))),80/A19) | R19: =IF(A19<=150,IF(ISNUMBER(Q19),Q19,""),MAX(IF(ISNUMBER(I19),I19,0),IF(ISNUMBER(P19),P19,0),IF(ISNUMBER(Q19),Q19,0))) | S19: =IF(OR(R19="",R19<=0),"",100/R19) | T19: =IF(A19<=150,"DN150 Table IW.4",IF(OR(R19="",R19<=0),"no flow",IF(R19=Q19,"Absolute minimum (80/ID)",IF(AND(ISNUMBER(I19),R19=I19),"Slime control (Sss)","Self-cleansing (Ssc)")))) | U19: =IF(PDWF_L_s<=0,"",(PDWF_L_s/1000)/V_max) | V19: =Calc!AZ19 | W19: =IF(V19=0,"",(1-COS(V19/2))/2) | X19: =IF(V19=0,"",($B19/4)*(1-SIN(V19)/V19)) | Y19: =IF(V19=0,"",IF(U19>=PI()*$B19^2/4,"n/a - full",((V_max*n_Manning)/(X19^(2/3)))^2*100)) | Z19: =IF(ISNUMBER(Y19),100/Y19,"") | AA19: =IF(R19<=0,"",(1/n_Manning)*(PI()*$B19^2/4)*($B19/4)^(2/3)*SQRT(R19/100)*1000) | AB19: =IF(OR(PWWF_L_s<=0,R19<=0),"",PWWF_L_s/AA19) | AC19: =IF(OR(PWWF_L_s<=0,R19<=0),"",IF(AB19>=1,">1 (full)",(1-COS(Calc!BQ19/2))/2)) | AD19: =IF(OR(PWWF_L_s<=0,R19<=0),"",IF(AB19>=1,PWWF_L_s/1000/(PI()*$B19^2/4),(PWWF_L_s/1000)/($B19^2*(Calc!BQ19-SIN(Calc!BQ19))/8))) | AE19: =IF(OR(PDWF_L_s<=0,R19<=0),"",PDWF_L_s/AA19) | AF19: =IF(PDWF_L_s<=0,"enter flow",IF(OR(F19>0.95,M19>0.95),"Pipe too small for PDWF",IF(AND(ISNUMBER(Y19),Y19<R19),"Smax < Smin - pipe too large for flow",IF(PWWF_L_s<=0,"PWWF not set",IF(AB19>1,"SURCHARGED at Smin - size up or steepen","OK")))))
A20: 450 | B20: =A20/1000 | C20: =$C$11 | D20: =Calc!R20 | E20: =IF(D20=0,"",$B20/2*(1-COS(D20/2))*1000) | F20: =IF(D20=0,"",(1-COS(D20/2))/2) | G20: =IF(D20=0,"",($B20/4)*(1-SIN(D20)/D20)) | H20: =IF(D20=0,"",(C20/1000)/($B20^2*(D20-SIN(D20))/8)) | I20: =IF(D20=0,"",K_sss/G20) | J20: =IF(D20=0,"",100/I20) | K20: =$C$12 | L20: =Calc!AI20 | M20: =IF(L20=0,"",(1-COS(L20/2))/2) | N20: =IF(L20=0,"",($B20/4)*(1-SIN(L20)/L20)) | O20: =IF(L20=0,"",(K20/1000)/($B20^2*(L20-SIN(L20))/8)) | P20: =IF(L20=0,"",K_sc/N20) | Q20: =IF(A20<=150,IF($C$14>=35,0.7,IF($C$14>=28,0.8,IF($C$14>=18,0.9,IF($C$14>=12,1,IF($C$14>=7,1.1,IF($C$14>=2,1.2,IF($C$14>=1,1.25,""))))))),80/A20) | R20: =IF(A20<=150,IF(ISNUMBER(Q20),Q20,""),MAX(IF(ISNUMBER(I20),I20,0),IF(ISNUMBER(P20),P20,0),IF(ISNUMBER(Q20),Q20,0))) | S20: =IF(OR(R20="",R20<=0),"",100/R20) | T20: =IF(A20<=150,"DN150 Table IW.4",IF(OR(R20="",R20<=0),"no flow",IF(R20=Q20,"Absolute minimum (80/ID)",IF(AND(ISNUMBER(I20),R20=I20),"Slime control (Sss)","Self-cleansing (Ssc)")))) | U20: =IF(PDWF_L_s<=0,"",(PDWF_L_s/1000)/V_max) | V20: =Calc!AZ20 | W20: =IF(V20=0,"",(1-COS(V20/2))/2) | X20: =IF(V20=0,"",($B20/4)*(1-SIN(V20)/V20)) | Y20: =IF(V20=0,"",IF(U20>=PI()*$B20^2/4,"n/a - full",((V_max*n_Manning)/(X20^(2/3)))^2*100)) | Z20: =IF(ISNUMBER(Y20),100/Y20,"") | AA20: =IF(R20<=0,"",(1/n_Manning)*(PI()*$B20^2/4)*($B20/4)^(2/3)*SQRT(R20/100)*1000) | AB20: =IF(OR(PWWF_L_s<=0,R20<=0),"",PWWF_L_s/AA20) | AC20: =IF(OR(PWWF_L_s<=0,R20<=0),"",IF(AB20>=1,">1 (full)",(1-COS(Calc!BQ20/2))/2)) | AD20: =IF(OR(PWWF_L_s<=0,R20<=0),"",IF(AB20>=1,PWWF_L_s/1000/(PI()*$B20^2/4),(PWWF_L_s/1000)/($B20^2*(Calc!BQ20-SIN(Calc!BQ20))/8))) | AE20: =IF(OR(PDWF_L_s<=0,R20<=0),"",PDWF_L_s/AA20) | AF20: =IF(PDWF_L_s<=0,"enter flow",IF(OR(F20>0.95,M20>0.95),"Pipe too small for PDWF",IF(AND(ISNUMBER(Y20),Y20<R20),"Smax < Smin - pipe too large for flow",IF(PWWF_L_s<=0,"PWWF not set",IF(AB20>1,"SURCHARGED at Smin - size up or steepen","OK")))))
A21: 525 | B21: =A21/1000 | C21: =$C$11 | D21: =Calc!R21 | E21: =IF(D21=0,"",$B21/2*(1-COS(D21/2))*1000) | F21: =IF(D21=0,"",(1-COS(D21/2))/2) | G21: =IF(D21=0,"",($B21/4)*(1-SIN(D21)/D21)) | H21: =IF(D21=0,"",(C21/1000)/($B21^2*(D21-SIN(D21))/8)) | I21: =IF(D21=0,"",K_sss/G21) | J21: =IF(D21=0,"",100/I21) | K21: =$C$12 | L21: =Calc!AI21 | M21: =IF(L21=0,"",(1-COS(L21/2))/2) | N21: =IF(L21=0,"",($B21/4)*(1-SIN(L21)/L21)) | O21: =IF(L21=0,"",(K21/1000)/($B21^2*(L21-SIN(L21))/8)) | P21: =IF(L21=0,"",K_sc/N21) | Q21: =IF(A21<=150,IF($C$14>=35,0.7,IF($C$14>=28,0.8,IF($C$14>=18,0.9,IF($C$14>=12,1,IF($C$14>=7,1.1,IF($C$14>=2,1.2,IF($C$14>=1,1.25,""))))))),80/A21) | R21: =IF(A21<=150,IF(ISNUMBER(Q21),Q21,""),MAX(IF(ISNUMBER(I21),I21,0),IF(ISNUMBER(P21),P21,0),IF(ISNUMBER(Q21),Q21,0))) | S21: =IF(OR(R21="",R21<=0),"",100/R21) | T21: =IF(A21<=150,"DN150 Table IW.4",IF(OR(R21="",R21<=0),"no flow",IF(R21=Q21,"Absolute minimum (80/ID)",IF(AND(ISNUMBER(I21),R21=I21),"Slime control (Sss)","Self-cleansing (Ssc)")))) | U21: =IF(PDWF_L_s<=0,"",(PDWF_L_s/1000)/V_max) | V21: =Calc!AZ21 | W21: =IF(V21=0,"",(1-COS(V21/2))/2) | X21: =IF(V21=0,"",($B21/4)*(1-SIN(V21)/V21)) | Y21: =IF(V21=0,"",IF(U21>=PI()*$B21^2/4,"n/a - full",((V_max*n_Manning)/(X21^(2/3)))^2*100)) | Z21: =IF(ISNUMBER(Y21),100/Y21,"") | AA21: =IF(R21<=0,"",(1/n_Manning)*(PI()*$B21^2/4)*($B21/4)^(2/3)*SQRT(R21/100)*1000) | AB21: =IF(OR(PWWF_L_s<=0,R21<=0),"",PWWF_L_s/AA21) | AC21: =IF(OR(PWWF_L_s<=0,R21<=0),"",IF(AB21>=1,">1 (full)",(1-COS(Calc!BQ21/2))/2)) | AD21: =IF(OR(PWWF_L_s<=0,R21<=0),"",IF(AB21>=1,PWWF_L_s/1000/(PI()*$B21^2/4),(PWWF_L_s/1000)/($B21^2*(Calc!BQ21-SIN(Calc!BQ21))/8))) | AE21: =IF(OR(PDWF_L_s<=0,R21<=0),"",PDWF_L_s/AA21) | AF21: =IF(PDWF_L_s<=0,"enter flow",IF(OR(F21>0.95,M21>0.95),"Pipe too small for PDWF",IF(AND(ISNUMBER(Y21),Y21<R21),"Smax < Smin - pipe too large for flow",IF(PWWF_L_s<=0,"PWWF not set",IF(AB21>1,"SURCHARGED at Smin - size up or steepen","OK")))))
A22: 600 | B22: =A22/1000 | C22: =$C$11 | D22: =Calc!R22 | E22: =IF(D22=0,"",$B22/2*(1-COS(D22/2))*1000) | F22: =IF(D22=0,"",(1-COS(D22/2))/2) | G22: =IF(D22=0,"",($B22/4)*(1-SIN(D22)/D22)) | H22: =IF(D22=0,"",(C22/1000)/($B22^2*(D22-SIN(D22))/8)) | I22: =IF(D22=0,"",K_sss/G22) | J22: =IF(D22=0,"",100/I22) | K22: =$C$12 | L22: =Calc!AI22 | M22: =IF(L22=0,"",(1-COS(L22/2))/2) | N22: =IF(L22=0,"",($B22/4)*(1-SIN(L22)/L22)) | O22: =IF(L22=0,"",(K22/1000)/($B22^2*(L22-SIN(L22))/8)) | P22: =IF(L22=0,"",K_sc/N22) | Q22: =IF(A22<=150,IF($C$14>=35,0.7,IF($C$14>=28,0.8,IF($C$14>=18,0.9,IF($C$14>=12,1,IF($C$14>=7,1.1,IF($C$14>=2,1.2,IF($C$14>=1,1.25,""))))))),80/A22) | R22: =IF(A22<=150,IF(ISNUMBER(Q22),Q22,""),MAX(IF(ISNUMBER(I22),I22,0),IF(ISNUMBER(P22),P22,0),IF(ISNUMBER(Q22),Q22,0))) | S22: =IF(OR(R22="",R22<=0),"",100/R22) | T22: =IF(A22<=150,"DN150 Table IW.4",IF(OR(R22="",R22<=0),"no flow",IF(R22=Q22,"Absolute minimum (80/ID)",IF(AND(ISNUMBER(I22),R22=I22),"Slime control (Sss)","Self-cleansing (Ssc)")))) | U22: =IF(PDWF_L_s<=0,"",(PDWF_L_s/1000)/V_max) | V22: =Calc!AZ22 | W22: =IF(V22=0,"",(1-COS(V22/2))/2) | X22: =IF(V22=0,"",($B22/4)*(1-SIN(V22)/V22)) | Y22: =IF(V22=0,"",IF(U22>=PI()*$B22^2/4,"n/a - full",((V_max*n_Manning)/(X22^(2/3)))^2*100)) | Z22: =IF(ISNUMBER(Y22),100/Y22,"") | AA22: =IF(R22<=0,"",(1/n_Manning)*(PI()*$B22^2/4)*($B22/4)^(2/3)*SQRT(R22/100)*1000) | AB22: =IF(OR(PWWF_L_s<=0,R22<=0),"",PWWF_L_s/AA22) | AC22: =IF(OR(PWWF_L_s<=0,R22<=0),"",IF(AB22>=1,">1 (full)",(1-COS(Calc!BQ22/2))/2)) | AD22: =IF(OR(PWWF_L_s<=0,R22<=0),"",IF(AB22>=1,PWWF_L_s/1000/(PI()*$B22^2/4),(PWWF_L_s/1000)/($B22^2*(Calc!BQ22-SIN(Calc!BQ22))/8))) | AE22: =IF(OR(PDWF_L_s<=0,R22<=0),"",PDWF_L_s/AA22) | AF22: =IF(PDWF_L_s<=0,"enter flow",IF(OR(F22>0.95,M22>0.95),"Pipe too small for PDWF",IF(AND(ISNUMBER(Y22),Y22<R22),"Smax < Smin - pipe too large for flow",IF(PWWF_L_s<=0,"PWWF not set",IF(AB22>1,"SURCHARGED at Smin - size up or steepen","OK")))))
A23: 675 | B23: =A23/1000 | C23: =$C$11 | D23: =Calc!R23 | E23: =IF(D23=0,"",$B23/2*(1-COS(D23/2))*1000) | F23: =IF(D23=0,"",(1-COS(D23/2))/2) | G23: =IF(D23=0,"",($B23/4)*(1-SIN(D23)/D23)) | H23: =IF(D23=0,"",(C23/1000)/($B23^2*(D23-SIN(D23))/8)) | I23: =IF(D23=0,"",K_sss/G23) | J23: =IF(D23=0,"",100/I23) | K23: =$C$12 | L23: =Calc!AI23 | M23: =IF(L23=0,"",(1-COS(L23/2))/2) | N23: =IF(L23=0,"",($B23/4)*(1-SIN(L23)/L23)) | O23: =IF(L23=0,"",(K23/1000)/($B23^2*(L23-SIN(L23))/8)) | P23: =IF(L23=0,"",K_sc/N23) | Q23: =IF(A23<=150,IF($C$14>=35,0.7,IF($C$14>=28,0.8,IF($C$14>=18,0.9,IF($C$14>=12,1,IF($C$14>=7,1.1,IF($C$14>=2,1.2,IF($C$14>=1,1.25,""))))))),80/A23) | R23: =IF(A23<=150,IF(ISNUMBER(Q23),Q23,""),MAX(IF(ISNUMBER(I23),I23,0),IF(ISNUMBER(P23),P23,0),IF(ISNUMBER(Q23),Q23,0))) | S23: =IF(OR(R23="",R23<=0),"",100/R23) | T23: =IF(A23<=150,"DN150 Table IW.4",IF(OR(R23="",R23<=0),"no flow",IF(R23=Q23,"Absolute minimum (80/ID)",IF(AND(ISNUMBER(I23),R23=I23),"Slime control (Sss)","Self-cleansing (Ssc)")))) | U23: =IF(PDWF_L_s<=0,"",(PDWF_L_s/1000)/V_max) | V23: =Calc!AZ23 | W23: =IF(V23=0,"",(1-COS(V23/2))/2) | X23: =IF(V23=0,"",($B23/4)*(1-SIN(V23)/V23)) | Y23: =IF(V23=0,"",IF(U23>=PI()*$B23^2/4,"n/a - full",((V_max*n_Manning)/(X23^(2/3)))^2*100)) | Z23: =IF(ISNUMBER(Y23),100/Y23,"") | AA23: =IF(R23<=0,"",(1/n_Manning)*(PI()*$B23^2/4)*($B23/4)^(2/3)*SQRT(R23/100)*1000) | AB23: =IF(OR(PWWF_L_s<=0,R23<=0),"",PWWF_L_s/AA23) | AC23: =IF(OR(PWWF_L_s<=0,R23<=0),"",IF(AB23>=1,">1 (full)",(1-COS(Calc!BQ23/2))/2)) | AD23: =IF(OR(PWWF_L_s<=0,R23<=0),"",IF(AB23>=1,PWWF_L_s/1000/(PI()*$B23^2/4),(PWWF_L_s/1000)/($B23^2*(Calc!BQ23-SIN(Calc!BQ23))/8))) | AE23: =IF(OR(PDWF_L_s<=0,R23<=0),"",PDWF_L_s/AA23) | AF23: =IF(PDWF_L_s<=0,"enter flow",IF(OR(F23>0.95,M23>0.95),"Pipe too small for PDWF",IF(AND(ISNUMBER(Y23),Y23<R23),"Smax < Smin - pipe too large for flow",IF(PWWF_L_s<=0,"PWWF not set",IF(AB23>1,"SURCHARGED at Smin - size up or steepen","OK")))))
A24: 750 | B24: =A24/1000 | C24: =$C$11 | D24: =Calc!R24 | E24: =IF(D24=0,"",$B24/2*(1-COS(D24/2))*1000) | F24: =IF(D24=0,"",(1-COS(D24/2))/2) | G24: =IF(D24=0,"",($B24/4)*(1-SIN(D24)/D24)) | H24: =IF(D24=0,"",(C24/1000)/($B24^2*(D24-SIN(D24))/8)) | I24: =IF(D24=0,"",K_sss/G24) | J24: =IF(D24=0,"",100/I24) | K24: =$C$12 | L24: =Calc!AI24 | M24: =IF(L24=0,"",(1-COS(L24/2))/2) | N24: =IF(L24=0,"",($B24/4)*(1-SIN(L24)/L24)) | O24: =IF(L24=0,"",(K24/1000)/($B24^2*(L24-SIN(L24))/8)) | P24: =IF(L24=0,"",K_sc/N24) | Q24: =IF(A24<=150,IF($C$14>=35,0.7,IF($C$14>=28,0.8,IF($C$14>=18,0.9,IF($C$14>=12,1,IF($C$14>=7,1.1,IF($C$14>=2,1.2,IF($C$14>=1,1.25,""))))))),80/A24) | R24: =IF(A24<=150,IF(ISNUMBER(Q24),Q24,""),MAX(IF(ISNUMBER(I24),I24,0),IF(ISNUMBER(P24),P24,0),IF(ISNUMBER(Q24),Q24,0))) | S24: =IF(OR(R24="",R24<=0),"",100/R24) | T24: =IF(A24<=150,"DN150 Table IW.4",IF(OR(R24="",R24<=0),"no flow",IF(R24=Q24,"Absolute minimum (80/ID)",IF(AND(ISNUMBER(I24),R24=I24),"Slime control (Sss)","Self-cleansing (Ssc)")))) | U24: =IF(PDWF_L_s<=0,"",(PDWF_L_s/1000)/V_max) | V24: =Calc!AZ24 | W24: =IF(V24=0,"",(1-COS(V24/2))/2) | X24: =IF(V24=0,"",($B24/4)*(1-SIN(V24)/V24)) | Y24: =IF(V24=0,"",IF(U24>=PI()*$B24^2/4,"n/a - full",((V_max*n_Manning)/(X24^(2/3)))^2*100)) | Z24: =IF(ISNUMBER(Y24),100/Y24,"") | AA24: =IF(R24<=0,"",(1/n_Manning)*(PI()*$B24^2/4)*($B24/4)^(2/3)*SQRT(R24/100)*1000) | AB24: =IF(OR(PWWF_L_s<=0,R24<=0),"",PWWF_L_s/AA24) | AC24: =IF(OR(PWWF_L_s<=0,R24<=0),"",IF(AB24>=1,">1 (full)",(1-COS(Calc!BQ24/2))/2)) | AD24: =IF(OR(PWWF_L_s<=0,R24<=0),"",IF(AB24>=1,PWWF_L_s/1000/(PI()*$B24^2/4),(PWWF_L_s/1000)/($B24^2*(Calc!BQ24-SIN(Calc!BQ24))/8))) | AE24: =IF(OR(PDWF_L_s<=0,R24<=0),"",PDWF_L_s/AA24) | AF24: =IF(PDWF_L_s<=0,"enter flow",IF(OR(F24>0.95,M24>0.95),"Pipe too small for PDWF",IF(AND(ISNUMBER(Y24),Y24<R24),"Smax < Smin - pipe too large for flow",IF(PWWF_L_s<=0,"PWWF not set",IF(AB24>1,"SURCHARGED at Smin - size up or steepen","OK")))))
A25: 900 | B25: =A25/1000 | C25: =$C$11 | D25: =Calc!R25 | E25: =IF(D25=0,"",$B25/2*(1-COS(D25/2))*1000) | F25: =IF(D25=0,"",(1-COS(D25/2))/2) | G25: =IF(D25=0,"",($B25/4)*(1-SIN(D25)/D25)) | H25: =IF(D25=0,"",(C25/1000)/($B25^2*(D25-SIN(D25))/8)) | I25: =IF(D25=0,"",K_sss/G25) | J25: =IF(D25=0,"",100/I25) | K25: =$C$12 | L25: =Calc!AI25 | M25: =IF(L25=0,"",(1-COS(L25/2))/2) | N25: =IF(L25=0,"",($B25/4)*(1-SIN(L25)/L25)) | O25: =IF(L25=0,"",(K25/1000)/($B25^2*(L25-SIN(L25))/8)) | P25: =IF(L25=0,"",K_sc/N25) | Q25: =IF(A25<=150,IF($C$14>=35,0.7,IF($C$14>=28,0.8,IF($C$14>=18,0.9,IF($C$14>=12,1,IF($C$14>=7,1.1,IF($C$14>=2,1.2,IF($C$14>=1,1.25,""))))))),80/A25) | R25: =IF(A25<=150,IF(ISNUMBER(Q25),Q25,""),MAX(IF(ISNUMBER(I25),I25,0),IF(ISNUMBER(P25),P25,0),IF(ISNUMBER(Q25),Q25,0))) | S25: =IF(OR(R25="",R25<=0),"",100/R25) | T25: =IF(A25<=150,"DN150 Table IW.4",IF(OR(R25="",R25<=0),"no flow",IF(R25=Q25,"Absolute minimum (80/ID)",IF(AND(ISNUMBER(I25),R25=I25),"Slime control (Sss)","Self-cleansing (Ssc)")))) | U25: =IF(PDWF_L_s<=0,"",(PDWF_L_s/1000)/V_max) | V25: =Calc!AZ25 | W25: =IF(V25=0,"",(1-COS(V25/2))/2) | X25: =IF(V25=0,"",($B25/4)*(1-SIN(V25)/V25)) | Y25: =IF(V25=0,"",IF(U25>=PI()*$B25^2/4,"n/a - full",((V_max*n_Manning)/(X25^(2/3)))^2*100)) | Z25: =IF(ISNUMBER(Y25),100/Y25,"") | AA25: =IF(R25<=0,"",(1/n_Manning)*(PI()*$B25^2/4)*($B25/4)^(2/3)*SQRT(R25/100)*1000) | AB25: =IF(OR(PWWF_L_s<=0,R25<=0),"",PWWF_L_s/AA25) | AC25: =IF(OR(PWWF_L_s<=0,R25<=0),"",IF(AB25>=1,">1 (full)",(1-COS(Calc!BQ25/2))/2)) | AD25: =IF(OR(PWWF_L_s<=0,R25<=0),"",IF(AB25>=1,PWWF_L_s/1000/(PI()*$B25^2/4),(PWWF_L_s/1000)/($B25^2*(Calc!BQ25-SIN(Calc!BQ25))/8))) | AE25: =IF(OR(PDWF_L_s<=0,R25<=0),"",PDWF_L_s/AA25) | AF25: =IF(PDWF_L_s<=0,"enter flow",IF(OR(F25>0.95,M25>0.95),"Pipe too small for PDWF",IF(AND(ISNUMBER(Y25),Y25<R25),"Smax < Smin - pipe too large for flow",IF(PWWF_L_s<=0,"PWWF not set",IF(AB25>1,"SURCHARGED at Smin - size up or steepen","OK")))))
A27: Notes
A28: 1. Icon Water Eq IW.5.5.3.2 (Sss = 0.0338/Rp) is a tractive-force criterion. Substituting S = K/Rp into Manning removes S: Q = (1/n) sqrt(K/100) A Rp^(1/6). Sheet 'Calc' solves this for the part-full angle theta; Rp and S then follow directly. This replaces the Wolfram Alpha step of the original sheet.
A29: 2. Solve for: Grade uses the table. Flow uses Rp = K/grade, then Manning, so a known grade returns the Qdmp at which that grade is exactly Sss (and, beside it, Ssc). Diameter returns the smallest DN that meets the grade you can build. Assuming a depth instead, on Design Table, needs no iteration at all.
A30: 3. Both grades use the same flow Qdmp (Eq IW.5.5.3.3). Ssc = 0.0135/Rp and Sss = 0.0338/Rp (Eqs IW.5.5.3.1 and 3.2). Absolute minimum for DN>150 is 80/ID with ID in mm (Eq IW.5.5.3.4). DN150 uses Table IW.4 by number of houses, not those equations.
A31: 4. Capacity: the design flow (PWWF) should be carried without surcharge. y/D and PDWF/Qfull are reported so a stricter limit can be applied if Icon requires one.
A32: 5. This workbook is for Icon Water (ACT) only. NSW and most other states publish a grade table or a different test, so those numbers are not calculated here.

Sheet Calc
A1: Iteration engine (do not edit). Each block solves the central angle theta of the part-full circle: an asymptotic starting value followed by 14 Newton steps in log-space on f(theta) = A(theta) * R(theta)^m = T. The last column of each block feeds 'Grade Calculator'.
A2: Block 1: slime control (m = 1/6, T1 = Q75 n / sqrt(K_sss/100)) | Block 2: self-cleansing (m = 1/6, K_sc) | Block 3: wetted area for V_max (m = 0, T3 = PDWF/V_max) | Block 4: Manning normal depth at PWWF on the governing grade (m = 2/3, T4 = PWWF n / sqrt(S)). 14 steps give about 1e-6 or better up to y/D = 0.97; beyond that the pipe is reported as too small for the flow.
A15: DN | B15: D (m) | C15: T1 | D15: theta0 | E15: step 1 | F15: step 2 | G15: step 3 | H15: step 4 | I15: step 5 | J15: step 6 | K15: step 7 | L15: step 8 | M15: step 9 | N15: step 10 | O15: step 11 | P15: step 12 | Q15: step 13 | R15: step 14 | T15: T2 | U15: theta0 | V15: step 1 | W15: step 2 | X15: step 3 | Y15: step 4 | Z15: step 5 | AA15: step 6 | AB15: step 7 | AC15: step 8 | AD15: step 9 | AE15: step 10 | AF15: step 11 | AG15: step 12 | AH15: step 13 | AI15: step 14 | AK15: A_target (Vmax) | AL15: theta0 | AM15: step 1 | AN15: step 2 | AO15: step 3 | AP15: step 4 | AQ15: step 5 | AR15: step 6 | AS15: step 7 | AT15: step 8 | AU15: step 9 | AV15: step 10 | AW15: step 11 | AX15: step 12 | AY15: step 13 | AZ15: step 14 | BB15: T4 | BC15: theta0 | BD15: step 1 | BE15: step 2 | BF15: step 3 | BG15: step 4 | BH15: step 5 | BI15: step 6 | BJ15: step 7 | BK15: step 8 | BL15: step 9 | BM15: step 10 | BN15: step 11 | BO15: step 12 | BP15: step 13 | BQ15: step 14
A16: ='Grade Calculator'!$A16 | B16: ='Grade Calculator'!$B16 | C16: =IF('Grade Calculator'!$C16<=0,0,('Grade Calculator'!$C16/1000)*n_Manning/SQRT(K_sss/100)) | D16: =IF($C16<=0,0,MIN(2*PI()-0.000001,MAX(0.000001,($C16*81.52230382/$B16^2.166666667)^(1/3.333333333)))) | E16: =IF($C16<=0,0,MIN(2*PI()-0.000001,MAX(0.000001,D16*($C16/(($B16^2*(D16-SIN(D16))/8)*(($B16/4)*(1-SIN(D16)/D16))^0.1666666667))^(1/MAX(((D16*(1-COS(D16))+0.1666666667*(SIN(D16)-D16*COS(D16)))/(D16-SIN(D16))),0.25))))) | F16: =IF($C16<=0,0,MIN(2*PI()-0.000001,MAX(0.000001,E16*($C16/(($B16^2*(E16-SIN(E16))/8)*(($B16/4)*(1-SIN(E16)/E16))^0.1666666667))^(1/MAX(((E16*(1-COS(E16))+0.1666666667*(SIN(E16)-E16*COS(E16)))/(E16-SIN(E16))),0.25))))) | G16: =IF($C16<=0,0,MIN(2*PI()-0.000001,MAX(0.000001,F16*($C16/(($B16^2*(F16-SIN(F16))/8)*(($B16/4)*(1-SIN(F16)/F16))^0.1666666667))^(1/MAX(((F16*(1-COS(F16))+0.1666666667*(SIN(F16)-F16*COS(F16)))/(F16-SIN(F16))),0.25))))) | H16: =IF($C16<=0,0,MIN(2*PI()-0.000001,MAX(0.000001,G16*($C16/(($B16^2*(G16-SIN(G16))/8)*(($B16/4)*(1-SIN(G16)/G16))^0.1666666667))^(1/MAX(((G16*(1-COS(G16))+0.1666666667*(SIN(G16)-G16*COS(G16)))/(G16-SIN(G16))),0.25))))) | I16: =IF($C16<=0,0,MIN(2*PI()-0.000001,MAX(0.000001,H16*($C16/(($B16^2*(H16-SIN(H16))/8)*(($B16/4)*(1-SIN(H16)/H16))^0.1666666667))^(1/MAX(((H16*(1-COS(H16))+0.1666666667*(SIN(H16)-H16*COS(H16)))/(H16-SIN(H16))),0.25))))) | J16: =IF($C16<=0,0,MIN(2*PI()-0.000001,MAX(0.000001,I16*($C16/(($B16^2*(I16-SIN(I16))/8)*(($B16/4)*(1-SIN(I16)/I16))^0.1666666667))^(1/MAX(((I16*(1-COS(I16))+0.1666666667*(SIN(I16)-I16*COS(I16)))/(I16-SIN(I16))),0.25))))) | K16: =IF($C16<=0,0,MIN(2*PI()-0.000001,MAX(0.000001,J16*($C16/(($B16^2*(J16-SIN(J16))/8)*(($B16/4)*(1-SIN(J16)/J16))^0.1666666667))^(1/MAX(((J16*(1-COS(J16))+0.1666666667*(SIN(J16)-J16*COS(J16)))/(J16-SIN(J16))),0.25))))) | L16: =IF($C16<=0,0,MIN(2*PI()-0.000001,MAX(0.000001,K16*($C16/(($B16^2*(K16-SIN(K16))/8)*(($B16/4)*(1-SIN(K16)/K16))^0.1666666667))^(1/MAX(((K16*(1-COS(K16))+0.1666666667*(SIN(K16)-K16*COS(K16)))/(K16-SIN(K16))),0.25))))) | ... R16: =IF($C16<=0,0,MIN(2*PI()-0.000001,MAX(0.000001,Q16*($C16/(($B16^2*(Q16-SIN(Q16))/8)*(($B16/4)*(1-SIN(Q16)/Q16))^0.1666666667))^(1/MAX(((Q16*(1-COS(Q16))+0.1666666667*(SIN(Q16)-Q16*COS(Q16)))/(Q16-SIN(Q16))),0.25))))) | T16: =IF('Grade Calculator'!$K16<=0,0,('Grade Calculator'!$K16/1000)*n_Manning/SQRT(K_sc/100)) | U16: =IF($T16<=0,0,MIN(2*PI()-0.000001,MAX(0.000001,($T16*81.52230382/$B16^2.166666667)^(1/3.333333333)))) | V16: =IF($T16<=0,0,MIN(2*PI()-0.000001,MAX(0.000001,U16*($T16/(($B16^2*(U16-SIN(U16))/8)*(($B16/4)*(1-SIN(U16)/U16))^0.1666666667))^(1/MAX(((U16*(1-COS(U16))+0.1666666667*(SIN(U16)-U16*COS(U16)))/(U16-SIN(U16))),0.25))))) | W16: =IF($T16<=0,0,MIN(2*PI()-0.000001,MAX(0.000001,V16*($T16/(($B16^2*(V16-SIN(V16))/8)*(($B16/4)*(1-SIN(V16)/V16))^0.1666666667))^(1/MAX(((V16*(1-COS(V16))+0.1666666667*(SIN(V16)-V16*COS(V16)))/(V16-SIN(V16))),0.25))))) | X16: =IF($T16<=0,0,MIN(2*PI()-0.000001,MAX(0.000001,W16*($T16/(($B16^2*(W16-SIN(W16))/8)*(($B16/4)*(1-SIN(W16)/W16))^0.1666666667))^(1/MAX(((W16*(1-COS(W16))+0.1666666667*(SIN(W16)-W16*COS(W16)))/(W16-SIN(W16))),0.25))))) | Y16: =IF($T16<=0,0,MIN(2*PI()-0.000001,MAX(0.000001,X16*($T16/(($B16^2*(X16-SIN(X16))/8)*(($B16/4)*(1-SIN(X16)/X16))^0.1666666667))^(1/MAX(((X16*(1-COS(X16))+0.1666666667*(SIN(X16)-X16*COS(X16)))/(X16-SIN(X16))),0.25))))) | Z16: =IF($T16<=0,0,MIN(2*PI()-0.000001,MAX(0.000001,Y16*($T16/(($B16^2*(Y16-SIN(Y16))/8)*(($B16/4)*(1-SIN(Y16)/Y16))^0.1666666667))^(1/MAX(((Y16*(1-COS(Y16))+0.1666666667*(SIN(Y16)-Y16*COS(Y16)))/(Y16-SIN(Y16))),0.25))))) | AA16: =IF($T16<=0,0,MIN(2*PI()-0.000001,MAX(0.000001,Z16*($T16/(($B16^2*(Z16-SIN(Z16))/8)*(($B16/4)*(1-SIN(Z16)/Z16))^0.1666666667))^(1/MAX(((Z16*(1-COS(Z16))+0.1666666667*(SIN(Z16)-Z16*COS(Z16)))/(Z16-SIN(Z16))),0.25))))) | AB16: =IF($T16<=0,0,MIN(2*PI()-0.000001,MAX(0.000001,AA16*($T16/(($B16^2*(AA16-SIN(AA16))/8)*(($B16/4)*(1-SIN(AA16)/AA16))^0.1666666667))^(1/MAX(((AA16*(1-COS(AA16))+0.1666666667*(SIN(AA16)-AA16*COS(AA16)))/(AA16-SIN(AA16))),0.25))))) | AC16: =IF($T16<=0,0,MIN(2*PI()-0.000001,MAX(0.000001,AB16*($T16/(($B16^2*(AB16-SIN(AB16))/8)*(($B16/4)*(1-SIN(AB16)/AB16))^0.1666666667))^(1/MAX(((AB16*(1-COS(AB16))+0.1666666667*(SIN(AB16)-AB16*COS(AB16)))/(AB16-SIN(AB16))),0.25))))) | ... AI16: =IF($T16<=0,0,MIN(2*PI()-0.000001,MAX(0.000001,AH16*($T16/(($B16^2*(AH16-SIN(AH16))/8)*(($B16/4)*(1-SIN(AH16)/AH16))^0.1666666667))^(1/MAX(((AH16*(1-COS(AH16))+0.1666666667*(SIN(AH16)-AH16*COS(AH16)))/(AH16-SIN(AH16))),0.25))))) | AK16: =IF(PDWF_L_s<=0,0,(PDWF_L_s/1000)/V_max) | AL16: =IF($AK16<=0,0,MIN(2*PI()-0.000001,MAX(0.000001,($AK16*48/$B16^2)^(1/3)))) | AM16: =IF($AK16<=0,0,MIN(2*PI()-0.000001,MAX(0.000001,AL16*($AK16/($B16^2*(AL16-SIN(AL16))/8))^(1/MAX((AL16*(1-COS(AL16))/(AL16-SIN(AL16))),0.25))))) | AN16: =IF($AK16<=0,0,MIN(2*PI()-0.000001,MAX(0.000001,AM16*($AK16/($B16^2*(AM16-SIN(AM16))/8))^(1/MAX((AM16*(1-COS(AM16))/(AM16-SIN(AM16))),0.25))))) | AO16: =IF($AK16<=0,0,MIN(2*PI()-0.000001,MAX(0.000001,AN16*($AK16/($B16^2*(AN16-SIN(AN16))/8))^(1/MAX((AN16*(1-COS(AN16))/(AN16-SIN(AN16))),0.25))))) | AP16: =IF($AK16<=0,0,MIN(2*PI()-0.000001,MAX(0.000001,AO16*($AK16/($B16^2*(AO16-SIN(AO16))/8))^(1/MAX((AO16*(1-COS(AO16))/(AO16-SIN(AO16))),0.25))))) | AQ16: =IF($AK16<=0,0,MIN(2*PI()-0.000001,MAX(0.000001,AP16*($AK16/($B16^2*(AP16-SIN(AP16))/8))^(1/MAX((AP16*(1-COS(AP16))/(AP16-SIN(AP16))),0.25))))) | AR16: =IF($AK16<=0,0,MIN(2*PI()-0.000001,MAX(0.000001,AQ16*($AK16/($B16^2*(AQ16-SIN(AQ16))/8))^(1/MAX((AQ16*(1-COS(AQ16))/(AQ16-SIN(AQ16))),0.25))))) | AS16: =IF($AK16<=0,0,MIN(2*PI()-0.000001,MAX(0.000001,AR16*($AK16/($B16^2*(AR16-SIN(AR16))/8))^(1/MAX((AR16*(1-COS(AR16))/(AR16-SIN(AR16))),0.25))))) | AT16: =IF($AK16<=0,0,MIN(2*PI()-0.000001,MAX(0.000001,AS16*($AK16/($B16^2*(AS16-SIN(AS16))/8))^(1/MAX((AS16*(1-COS(AS16))/(AS16-SIN(AS16))),0.25))))) | ... AZ16: =IF($AK16<=0,0,MIN(2*PI()-0.000001,MAX(0.000001,AY16*($AK16/($B16^2*(AY16-SIN(AY16))/8))^(1/MAX((AY16*(1-COS(AY16))/(AY16-SIN(AY16))),0.25))))) | BB16: =IF(OR(PWWF_L_s<=0,'Grade Calculator'!$R16<=0),0,(PWWF_L_s/1000)*n_Manning/SQRT('Grade Calculator'!$R16/100)) | BC16: =IF($BB16<=0,0,MIN(2*PI()-0.000001,MAX(0.000001,($BB16*399.376094/$B16^2.666666667)^(1/4.333333333)))) | BD16: =IF($BB16<=0,0,MIN(2*PI()-0.000001,MAX(0.000001,BC16*($BB16/(($B16^2*(BC16-SIN(BC16))/8)*(($B16/4)*(1-SIN(BC16)/BC16))^0.6666666667))^(1/MAX(((BC16*(1-COS(BC16))+0.6666666667*(SIN(BC16)-BC16*COS(BC16)))/(BC16-SIN(BC16))),0.25))))) | BE16: =IF($BB16<=0,0,MIN(2*PI()-0.000001,MAX(0.000001,BD16*($BB16/(($B16^2*(BD16-SIN(BD16))/8)*(($B16/4)*(1-SIN(BD16)/BD16))^0.6666666667))^(1/MAX(((BD16*(1-COS(BD16))+0.6666666667*(SIN(BD16)-BD16*COS(BD16)))/(BD16-SIN(BD16))),0.25))))) | BF16: =IF($BB16<=0,0,MIN(2*PI()-0.000001,MAX(0.000001,BE16*($BB16/(($B16^2*(BE16-SIN(BE16))/8)*(($B16/4)*(1-SIN(BE16)/BE16))^0.6666666667))^(1/MAX(((BE16*(1-COS(BE16))+0.6666666667*(SIN(BE16)-BE16*COS(BE16)))/(BE16-SIN(BE16))),0.25))))) | BG16: =IF($BB16<=0,0,MIN(2*PI()-0.000001,MAX(0.000001,BF16*($BB16/(($B16^2*(BF16-SIN(BF16))/8)*(($B16/4)*(1-SIN(BF16)/BF16))^0.6666666667))^(1/MAX(((BF16*(1-COS(BF16))+0.6666666667*(SIN(BF16)-BF16*COS(BF16)))/(BF16-SIN(BF16))),0.25))))) | BH16: =IF($BB16<=0,0,MIN(2*PI()-0.000001,MAX(0.000001,BG16*($BB16/(($B16^2*(BG16-SIN(BG16))/8)*(($B16/4)*(1-SIN(BG16)/BG16))^0.6666666667))^(1/MAX(((BG16*(1-COS(BG16))+0.6666666667*(SIN(BG16)-BG16*COS(BG16)))/(BG16-SIN(BG16))),0.25))))) | BI16: =IF($BB16<=0,0,MIN(2*PI()-0.000001,MAX(0.000001,BH16*($BB16/(($B16^2*(BH16-SIN(BH16))/8)*(($B16/4)*(1-SIN(BH16)/BH16))^0.6666666667))^(1/MAX(((BH16*(1-COS(BH16))+0.6666666667*(SIN(BH16)-BH16*COS(BH16)))/(BH16-SIN(BH16))),0.25))))) | BJ16: =IF($BB16<=0,0,MIN(2*PI()-0.000001,MAX(0.000001,BI16*($BB16/(($B16^2*(BI16-SIN(BI16))/8)*(($B16/4)*(1-SIN(BI16)/BI16))^0.6666666667))^(1/MAX(((BI16*(1-COS(BI16))+0.6666666667*(SIN(BI16)-BI16*COS(BI16)))/(BI16-SIN(BI16))),0.25))))) | BK16: =IF($BB16<=0,0,MIN(2*PI()-0.000001,MAX(0.000001,BJ16*($BB16/(($B16^2*(BJ16-SIN(BJ16))/8)*(($B16/4)*(1-SIN(BJ16)/BJ16))^0.6666666667))^(1/MAX(((BJ16*(1-COS(BJ16))+0.6666666667*(SIN(BJ16)-BJ16*COS(BJ16)))/(BJ16-SIN(BJ16))),0.25))))) | ... BQ16: =IF($BB16<=0,0,MIN(2*PI()-0.000001,MAX(0.000001,BP16*($BB16/(($B16^2*(BP16-SIN(BP16))/8)*(($B16/4)*(1-SIN(BP16)/BP16))^0.6666666667))^(1/MAX(((BP16*(1-COS(BP16))+0.6666666667*(SIN(BP16)-BP16*COS(BP16)))/(BP16-SIN(BP16))),0.25)))))
A17: ='Grade Calculator'!$A17 | B17: ='Grade Calculator'!$B17 | C17: =IF('Grade Calculator'!$C17<=0,0,('Grade Calculator'!$C17/1000)*n_Manning/SQRT(K_sss/100)) | D17: =IF($C17<=0,0,MIN(2*PI()-0.000001,MAX(0.000001,($C17*81.52230382/$B17^2.166666667)^(1/3.333333333)))) | E17: =IF($C17<=0,0,MIN(2*PI()-0.000001,MAX(0.000001,D17*($C17/(($B17^2*(D17-SIN(D17))/8)*(($B17/4)*(1-SIN(D17)/D17))^0.1666666667))^(1/MAX(((D17*(1-COS(D17))+0.1666666667*(SIN(D17)-D17*COS(D17)))/(D17-SIN(D17))),0.25))))) | F17: =IF($C17<=0,0,MIN(2*PI()-0.000001,MAX(0.000001,E17*($C17/(($B17^2*(E17-SIN(E17))/8)*(($B17/4)*(1-SIN(E17)/E17))^0.1666666667))^(1/MAX(((E17*(1-COS(E17))+0.1666666667*(SIN(E17)-E17*COS(E17)))/(E17-SIN(E17))),0.25))))) | G17: =IF($C17<=0,0,MIN(2*PI()-0.000001,MAX(0.000001,F17*($C17/(($B17^2*(F17-SIN(F17))/8)*(($B17/4)*(1-SIN(F17)/F17))^0.1666666667))^(1/MAX(((F17*(1-COS(F17))+0.1666666667*(SIN(F17)-F17*COS(F17)))/(F17-SIN(F17))),0.25))))) | H17: =IF($C17<=0,0,MIN(2*PI()-0.000001,MAX(0.000001,G17*($C17/(($B17^2*(G17-SIN(G17))/8)*(($B17/4)*(1-SIN(G17)/G17))^0.1666666667))^(1/MAX(((G17*(1-COS(G17))+0.1666666667*(SIN(G17)-G17*COS(G17)))/(G17-SIN(G17))),0.25))))) | I17: =IF($C17<=0,0,MIN(2*PI()-0.000001,MAX(0.000001,H17*($C17/(($B17^2*(H17-SIN(H17))/8)*(($B17/4)*(1-SIN(H17)/H17))^0.1666666667))^(1/MAX(((H17*(1-COS(H17))+0.1666666667*(SIN(H17)-H17*COS(H17)))/(H17-SIN(H17))),0.25))))) | J17: =IF($C17<=0,0,MIN(2*PI()-0.000001,MAX(0.000001,I17*($C17/(($B17^2*(I17-SIN(I17))/8)*(($B17/4)*(1-SIN(I17)/I17))^0.1666666667))^(1/MAX(((I17*(1-COS(I17))+0.1666666667*(SIN(I17)-I17*COS(I17)))/(I17-SIN(I17))),0.25))))) | K17: =IF($C17<=0,0,MIN(2*PI()-0.000001,MAX(0.000001,J17*($C17/(($B17^2*(J17-SIN(J17))/8)*(($B17/4)*(1-SIN(J17)/J17))^0.1666666667))^(1/MAX(((J17*(1-COS(J17))+0.1666666667*(SIN(J17)-J17*COS(J17)))/(J17-SIN(J17))),0.25))))) | L17: =IF($C17<=0,0,MIN(2*PI()-0.000001,MAX(0.000001,K17*($C17/(($B17^2*(K17-SIN(K17))/8)*(($B17/4)*(1-SIN(K17)/K17))^0.1666666667))^(1/MAX(((K17*(1-COS(K17))+0.1666666667*(SIN(K17)-K17*COS(K17)))/(K17-SIN(K17))),0.25))))) | ... R17: =IF($C17<=0,0,MIN(2*PI()-0.000001,MAX(0.000001,Q17*($C17/(($B17^2*(Q17-SIN(Q17))/8)*(($B17/4)*(1-SIN(Q17)/Q17))^0.1666666667))^(1/MAX(((Q17*(1-COS(Q17))+0.1666666667*(SIN(Q17)-Q17*COS(Q17)))/(Q17-SIN(Q17))),0.25))))) | T17: =IF('Grade Calculator'!$K17<=0,0,('Grade Calculator'!$K17/1000)*n_Manning/SQRT(K_sc/100)) | U17: =IF($T17<=0,0,MIN(2*PI()-0.000001,MAX(0.000001,($T17*81.52230382/$B17^2.166666667)^(1/3.333333333)))) | V17: =IF($T17<=0,0,MIN(2*PI()-0.000001,MAX(0.000001,U17*($T17/(($B17^2*(U17-SIN(U17))/8)*(($B17/4)*(1-SIN(U17)/U17))^0.1666666667))^(1/MAX(((U17*(1-COS(U17))+0.1666666667*(SIN(U17)-U17*COS(U17)))/(U17-SIN(U17))),0.25))))) | W17: =IF($T17<=0,0,MIN(2*PI()-0.000001,MAX(0.000001,V17*($T17/(($B17^2*(V17-SIN(V17))/8)*(($B17/4)*(1-SIN(V17)/V17))^0.1666666667))^(1/MAX(((V17*(1-COS(V17))+0.1666666667*(SIN(V17)-V17*COS(V17)))/(V17-SIN(V17))),0.25))))) | X17: =IF($T17<=0,0,MIN(2*PI()-0.000001,MAX(0.000001,W17*($T17/(($B17^2*(W17-SIN(W17))/8)*(($B17/4)*(1-SIN(W17)/W17))^0.1666666667))^(1/MAX(((W17*(1-COS(W17))+0.1666666667*(SIN(W17)-W17*COS(W17)))/(W17-SIN(W17))),0.25))))) | Y17: =IF($T17<=0,0,MIN(2*PI()-0.000001,MAX(0.000001,X17*($T17/(($B17^2*(X17-SIN(X17))/8)*(($B17/4)*(1-SIN(X17)/X17))^0.1666666667))^(1/MAX(((X17*(1-COS(X17))+0.1666666667*(SIN(X17)-X17*COS(X17)))/(X17-SIN(X17))),0.25))))) | Z17: =IF($T17<=0,0,MIN(2*PI()-0.000001,MAX(0.000001,Y17*($T17/(($B17^2*(Y17-SIN(Y17))/8)*(($B17/4)*(1-SIN(Y17)/Y17))^0.1666666667))^(1/MAX(((Y17*(1-COS(Y17))+0.1666666667*(SIN(Y17)-Y17*COS(Y17)))/(Y17-SIN(Y17))),0.25))))) | AA17: =IF($T17<=0,0,MIN(2*PI()-0.000001,MAX(0.000001,Z17*($T17/(($B17^2*(Z17-SIN(Z17))/8)*(($B17/4)*(1-SIN(Z17)/Z17))^0.1666666667))^(1/MAX(((Z17*(1-COS(Z17))+0.1666666667*(SIN(Z17)-Z17*COS(Z17)))/(Z17-SIN(Z17))),0.25))))) | AB17: =IF($T17<=0,0,MIN(2*PI()-0.000001,MAX(0.000001,AA17*($T17/(($B17^2*(AA17-SIN(AA17))/8)*(($B17/4)*(1-SIN(AA17)/AA17))^0.1666666667))^(1/MAX(((AA17*(1-COS(AA17))+0.1666666667*(SIN(AA17)-AA17*COS(AA17)))/(AA17-SIN(AA17))),0.25))))) | AC17: =IF($T17<=0,0,MIN(2*PI()-0.000001,MAX(0.000001,AB17*($T17/(($B17^2*(AB17-SIN(AB17))/8)*(($B17/4)*(1-SIN(AB17)/AB17))^0.1666666667))^(1/MAX(((AB17*(1-COS(AB17))+0.1666666667*(SIN(AB17)-AB17*COS(AB17)))/(AB17-SIN(AB17))),0.25))))) | ... AI17: =IF($T17<=0,0,MIN(2*PI()-0.000001,MAX(0.000001,AH17*($T17/(($B17^2*(AH17-SIN(AH17))/8)*(($B17/4)*(1-SIN(AH17)/AH17))^0.1666666667))^(1/MAX(((AH17*(1-COS(AH17))+0.1666666667*(SIN(AH17)-AH17*COS(AH17)))/(AH17-SIN(AH17))),0.25))))) | AK17: =IF(PDWF_L_s<=0,0,(PDWF_L_s/1000)/V_max) | AL17: =IF($AK17<=0,0,MIN(2*PI()-0.000001,MAX(0.000001,($AK17*48/$B17^2)^(1/3)))) | AM17: =IF($AK17<=0,0,MIN(2*PI()-0.000001,MAX(0.000001,AL17*($AK17/($B17^2*(AL17-SIN(AL17))/8))^(1/MAX((AL17*(1-COS(AL17))/(AL17-SIN(AL17))),0.25))))) | AN17: =IF($AK17<=0,0,MIN(2*PI()-0.000001,MAX(0.000001,AM17*($AK17/($B17^2*(AM17-SIN(AM17))/8))^(1/MAX((AM17*(1-COS(AM17))/(AM17-SIN(AM17))),0.25))))) | AO17: =IF($AK17<=0,0,MIN(2*PI()-0.000001,MAX(0.000001,AN17*($AK17/($B17^2*(AN17-SIN(AN17))/8))^(1/MAX((AN17*(1-COS(AN17))/(AN17-SIN(AN17))),0.25))))) | AP17: =IF($AK17<=0,0,MIN(2*PI()-0.000001,MAX(0.000001,AO17*($AK17/($B17^2*(AO17-SIN(AO17))/8))^(1/MAX((AO17*(1-COS(AO17))/(AO17-SIN(AO17))),0.25))))) | AQ17: =IF($AK17<=0,0,MIN(2*PI()-0.000001,MAX(0.000001,AP17*($AK17/($B17^2*(AP17-SIN(AP17))/8))^(1/MAX((AP17*(1-COS(AP17))/(AP17-SIN(AP17))),0.25))))) | AR17: =IF($AK17<=0,0,MIN(2*PI()-0.000001,MAX(0.000001,AQ17*($AK17/($B17^2*(AQ17-SIN(AQ17))/8))^(1/MAX((AQ17*(1-COS(AQ17))/(AQ17-SIN(AQ17))),0.25))))) | AS17: =IF($AK17<=0,0,MIN(2*PI()-0.000001,MAX(0.000001,AR17*($AK17/($B17^2*(AR17-SIN(AR17))/8))^(1/MAX((AR17*(1-COS(AR17))/(AR17-SIN(AR17))),0.25))))) | AT17: =IF($AK17<=0,0,MIN(2*PI()-0.000001,MAX(0.000001,AS17*($AK17/($B17^2*(AS17-SIN(AS17))/8))^(1/MAX((AS17*(1-COS(AS17))/(AS17-SIN(AS17))),0.25))))) | ... AZ17: =IF($AK17<=0,0,MIN(2*PI()-0.000001,MAX(0.000001,AY17*($AK17/($B17^2*(AY17-SIN(AY17))/8))^(1/MAX((AY17*(1-COS(AY17))/(AY17-SIN(AY17))),0.25))))) | BB17: =IF(OR(PWWF_L_s<=0,'Grade Calculator'!$R17<=0),0,(PWWF_L_s/1000)*n_Manning/SQRT('Grade Calculator'!$R17/100)) | BC17: =IF($BB17<=0,0,MIN(2*PI()-0.000001,MAX(0.000001,($BB17*399.376094/$B17^2.666666667)^(1/4.333333333)))) | BD17: =IF($BB17<=0,0,MIN(2*PI()-0.000001,MAX(0.000001,BC17*($BB17/(($B17^2*(BC17-SIN(BC17))/8)*(($B17/4)*(1-SIN(BC17)/BC17))^0.6666666667))^(1/MAX(((BC17*(1-COS(BC17))+0.6666666667*(SIN(BC17)-BC17*COS(BC17)))/(BC17-SIN(BC17))),0.25))))) | BE17: =IF($BB17<=0,0,MIN(2*PI()-0.000001,MAX(0.000001,BD17*($BB17/(($B17^2*(BD17-SIN(BD17))/8)*(($B17/4)*(1-SIN(BD17)/BD17))^0.6666666667))^(1/MAX(((BD17*(1-COS(BD17))+0.6666666667*(SIN(BD17)-BD17*COS(BD17)))/(BD17-SIN(BD17))),0.25))))) | BF17: =IF($BB17<=0,0,MIN(2*PI()-0.000001,MAX(0.000001,BE17*($BB17/(($B17^2*(BE17-SIN(BE17))/8)*(($B17/4)*(1-SIN(BE17)/BE17))^0.6666666667))^(1/MAX(((BE17*(1-COS(BE17))+0.6666666667*(SIN(BE17)-BE17*COS(BE17)))/(BE17-SIN(BE17))),0.25))))) | BG17: =IF($BB17<=0,0,MIN(2*PI()-0.000001,MAX(0.000001,BF17*($BB17/(($B17^2*(BF17-SIN(BF17))/8)*(($B17/4)*(1-SIN(BF17)/BF17))^0.6666666667))^(1/MAX(((BF17*(1-COS(BF17))+0.6666666667*(SIN(BF17)-BF17*COS(BF17)))/(BF17-SIN(BF17))),0.25))))) | BH17: =IF($BB17<=0,0,MIN(2*PI()-0.000001,MAX(0.000001,BG17*($BB17/(($B17^2*(BG17-SIN(BG17))/8)*(($B17/4)*(1-SIN(BG17)/BG17))^0.6666666667))^(1/MAX(((BG17*(1-COS(BG17))+0.6666666667*(SIN(BG17)-BG17*COS(BG17)))/(BG17-SIN(BG17))),0.25))))) | BI17: =IF($BB17<=0,0,MIN(2*PI()-0.000001,MAX(0.000001,BH17*($BB17/(($B17^2*(BH17-SIN(BH17))/8)*(($B17/4)*(1-SIN(BH17)/BH17))^0.6666666667))^(1/MAX(((BH17*(1-COS(BH17))+0.6666666667*(SIN(BH17)-BH17*COS(BH17)))/(BH17-SIN(BH17))),0.25))))) | BJ17: =IF($BB17<=0,0,MIN(2*PI()-0.000001,MAX(0.000001,BI17*($BB17/(($B17^2*(BI17-SIN(BI17))/8)*(($B17/4)*(1-SIN(BI17)/BI17))^0.6666666667))^(1/MAX(((BI17*(1-COS(BI17))+0.6666666667*(SIN(BI17)-BI17*COS(BI17)))/(BI17-SIN(BI17))),0.25))))) | BK17: =IF($BB17<=0,0,MIN(2*PI()-0.000001,MAX(0.000001,BJ17*($BB17/(($B17^2*(BJ17-SIN(BJ17))/8)*(($B17/4)*(1-SIN(BJ17)/BJ17))^0.6666666667))^(1/MAX(((BJ17*(1-COS(BJ17))+0.6666666667*(SIN(BJ17)-BJ17*COS(BJ17)))/(BJ17-SIN(BJ17))),0.25))))) | ... BQ17: =IF($BB17<=0,0,MIN(2*PI()-0.000001,MAX(0.000001,BP17*($BB17/(($B17^2*(BP17-SIN(BP17))/8)*(($B17/4)*(1-SIN(BP17)/BP17))^0.6666666667))^(1/MAX(((BP17*(1-COS(BP17))+0.6666666667*(SIN(BP17)-BP17*COS(BP17)))/(BP17-SIN(BP17))),0.25)))))
